Workbook

Sheet Rosto
E4: SIMULADOR DE INVESTIMENTOS em Fundos Imobiliários
E13: Vamos ajudá-lo a construir uma estratégia de investimento de acordo com seu perfil e seus objetivos.
G18: CLIQUE AQUI PARA COMEÇAR

Sheet Perfil do Investidor
AA1: Resposta | AB1: Pontos
G2: Qual é o seu perfil de investidor? | AA2: ESCOLHA | AB2: 0
AA3: A | AB3: 1 | AD3: =IFERROR(VLOOKUP(J13,$AA$2:$AB$5,2,FALSE),0) -> 0
AA4: B | AB4: 2 | AD4: =IFERROR(VLOOKUP(M18,$AA$2:$AB$5,2,FALSE),0) -> 0
C5: VAMOS DESCUBRIR O SEU PERFIL DE INVESTIDOR | I5: =IF(AND(OR(J13="A",J13="B",J13="C"),OR(J23="A",J23="B",J23="C"),OR(J28="A",J28="B",J28="C"),OR(I33="A",I33="B",I33="C"),OR(I38="A",I38="B",I38="C"),OR(L43="A",L43="B",L43="C"),OR(N48="A",N48="B",N48="C")),IF($AD$11<=13,"CONSERVADOR",IF($AD$11<=19,"MODERADO","AGRESSIVO")),"") | O5: CONTINUAR | Q5: Voltar para página anterior | AA5: C | AB5: 3 | AD5: =IFERROR(VLOOKUP(J23,$AA$2:$AB$5,2,FALSE),0) -> 0
AD6: =IFERROR(VLOOKUP(J28,$AA$2:$AB$5,2,FALSE),0) -> 0
C7: O objetivo é identificar o nível de risco que você está disposto a assumir em seus investimentos. | AD7: =IFERROR(VLOOKUP(I33,$AA$2:$AB$5,2,FALSE),0) -> 0
C8: Escolha uma alternativa às perguntas abaixo. Não existem respostas certas ou erradas. | AD8: =IFERROR(VLOOKUP(I38,$AA$2:$AB$5,2,FALSE),0) -> 0
AD9: =IFERROR(VLOOKUP(L43,$AA$2:$AB$5,2,FALSE),0) -> 0
C10: INSTRUÇÃO | AD10: =IFERROR(VLOOKUP(N48,$AA$2:$AB$5,2,FALSE),0) -> 0
C11: Escolha a melhor alternativa que representa seu pensamento, clique na celula ESCOLHA, vai aparecer flexinha e escolha sua opção. | AC11: TOTAL | AD11: =SUM(AD3:AD10) -> 0
C13: Pergunta 1 — Por quanto tempo pretende manter seus investimentos? | J13: ESCOLHA
C14: A. Menos de 2 anos
C15: B. Entre 2 e 5 anos
C16: C. Mais de 5 anos
C18: Pergunta 2 — Como você se sentiria se seu investimento perdesse 10% de valor temporariamente? | M18: ESCOLHA
C19: A. Ficaria muito preocupado e provavelmente venderia.
C20: B. Ficaria preocupado, mas aguardaria a recuperação.
C21: C. Aceitaria a queda e manteria o investimento.
C23: Pergunta 3 — Qual destas opções melhor descreve sua prioridade? | J23: ESCOLHA
C24: A. Preservar meu patrimônio.
C25: B. Equilibrar segurança e crescimento.
C26: C. Buscar maior crescimento, mesmo assumindo mais riscos.
C28: Pergunta 4 — Se existissem duas alternativas de investimento: | J28: ESCOLHA
C29: A. Retorno menor, mas maior previsibilidade.
C30: B. Retorno intermediário e risco intermediário.
C31: C. Maior potencial de retorno, mas com maior oscilação.
C33: Pergunta 5 — Como você reagiria a uma queda do mercado? | I33: ESCOLHA
C34: A. Venderia para evitar perdas maiores.
C35: B. Manteria os investimentos e aguardaria.
C36: C. Consideraria a queda uma oportunidade para investir mais.
C38: Pergunta 6 — Qual é sua experiência com investimentos? | I38: ESCOLHA
C39: A. Pouca ou nenhuma.
C40: B. Tenho alguma experiência.
C41: C. Tenho bastante experiência e acompanho meus investimentos.
C43: Pergunta 7 — Qual é a importância de receber uma renda periódica dos seus investimentos? | L43: ESCOLHA
C44: A. É muito importante para mim.
C45: B. É importante, mas também quero crescimento do patrimônio.
C46: C. Minha prioridade é crescimento do patrimônio.
C48: Pergunta 8 — Se um investimento apresentar maior potencial de retorno, mas também maior risco, você: | N48: ESCOLHA
...

Sheet Objetivo do Investimento
B2: ='Perfil do Investidor'!I5 | D2: QUAL É O SEU OBJETIVO DE INVESTIMENTO? | J2: CONTINUAR | L2: Voltar para página anterior
C4: Para que possamos construir uma simulação adequada, conte-nos o que você pretende alcançar com seus investimentos. | AA4: ESCOLHA | AE4: ESCOLHA
AA5: Formar patrimônio | AE5: Reenvistir 100%
C6: 1) Escolha o objetivo que melhor representa o que você deseja alcançar com seus investimentos. | AA6: Gerar renda mensal | AE6: Reinvestir parte
AA7: Complementar minha renda futura | AE7: Utilizar os rendimentos
D8: Escolha a alternativa | G8: ESCOLHA | AA8: Alcançar um patrimônio específico
D10: =IF(G8="Alcançar um patrimônio específico","Qual patrimônio você deseja alcançar?",IF(G8="Gerar renda mensal","Qual renda mensal você gostaria de alcançar?",IF(G8="Complementar minha renda futura","Qual renda mensal complementar você gostaria de obter?","")))
C11: 2) O que você pretende fazer com os rendimentos recebidos? | AA11: ESCOLHA
AA12: 2 anos
D13: Escolha a alternativa | G13: ESCOLHA | AA13: 5 anos
AA14: 10 anos
C15: 3) Quanto você pretende investir inicialmente? | AA15: 15 anos
AA16: 20 anos
D17: Informe o Valor | AA17: 30 anos
AA18: Outro prazo
C19: 4) Quanto você pretende investir todos os meses?
D21: Informe o Valor
C23: 5) Por quanto tempo pretende manter os investimentos?
D25: Escolha a alternativa | G25: ESCOLHA

Sheet Premissas da Simulação
AA1: PERFIL | AB1: RENTABILIDADE MENSAL | AC1: DY MENSAL
B2: ='Objetivo do Investimento'!B2 | D2: PREMISSAS DA SIMULAÇÃO | M2: CONTINUAR | O2: Voltar para página anterior | AA2: Conservador | AB2: 0.006 | AC2: 0.006
AA3: Moderado | AB3: 0.008 | AC3: 0.008
AA4: Agressivo | AB4: 0.01 | AC4: 0.01
C5: As taxas utilizadas são premissas para simulação e não representam garantia ou recomendação de investimento.
C8: Rentabilidade mensal estimada: | G8: =IFERROR(VLOOKUP(B2,$AA$2:$AC$4,2,FALSE),0) -> 0
C11: Dividend Yield mensal estimado: | G11: =IFERROR(VLOOKUP(B2,$AA$2:$AC$4,3,FALSE),0) -> 0

Sheet Carteira sugerida
B2: ='Premissas da Simulação'!B2 | D2: SUA CARTEIRA SUGERIDA | L2: CONTINUAR
C5: Tipo de FII | D5: Participação | L5: Voltar para página anterior
C6: PAPEL | D6: =IFERROR(INDEX(Variáveis!$B$2:$D$7,MATCH(C6,Variáveis!$A$2:$A$7,0),MATCH($B$2,Variáveis!$B$1:$D$1,0)),0) -> 0
C7: TIJOLO | D7: =IFERROR(INDEX(Variáveis!$B$2:$D$7,MATCH(C7,Variáveis!$A$2:$A$7,0),MATCH($B$2,Variáveis!$B$1:$D$1,0)),0) -> 0
C8: HÍBRIDOS | D8: =IFERROR(INDEX(Variáveis!$B$2:$D$7,MATCH(C8,Variáveis!$A$2:$A$7,0),MATCH($B$2,Variáveis!$B$1:$D$1,0)),0) -> 0
C9: FOFs | D9: =IFERROR(INDEX(Variáveis!$B$2:$D$7,MATCH(C9,Variáveis!$A$2:$A$7,0),MATCH($B$2,Variáveis!$B$1:$D$1,0)),0) -> 0
C10: DESENVOLVIMENTO | D10: =IFERROR(INDEX(Variáveis!$B$2:$D$7,MATCH(C10,Variáveis!$A$2:$A$7,0),MATCH($B$2,Variáveis!$B$1:$D$1,0)),0) -> 0
C11: HOTELARIA | D11: =IFERROR(INDEX(Variáveis!$B$2:$D$7,MATCH(C11,Variáveis!$A$2:$A$7,0),MATCH($B$2,Variáveis!$B$1:$D$1,0)),0) -> 0
C12: TOTAL | D12: =SUM(D6:D11) -> 0

Sheet Simulação
D2: SIMULAÇÃO DO SEU INVESTIMENTO | K2: CONTINUAR
C3: Com base nas informações que você forneceu, vamos projetar a evolução do seu investimento.
C5: Informação | K5: Voltar para página anterior
C6: Investimento inicial | E6: ='Objetivo do Investimento'!G17 -> 0
C7: Aporte mensal | E7: ='Objetivo do Investimento'!G21 -> 0
C8: Prazo do investimento | E8: ='Objetivo do Investimento'!G25 -> ESCOLHA
C9: Objetivo | E9: ='Objetivo do Investimento'!G8 -> ESCOLHA
C10: Meta financeira | E10: ='Objetivo do Investimento'!H10 -> 0
B12: Patrimônio acumulado ao final do período | E12: =IF(OR(E6=0,E7=0,E8="ESCOLHA",E9="ESCOLHA"),"",IFERROR(FV('Premissas da Simulação'!G8,VALUE(LEFT(E8,FIND(" ",E8)-1))*12,-E7,-E6),""))
B13: Total investido | E13: =IF(OR(E6=0,E7=0,E8="ESCOLHA"),"",E6+(E7*VALUE(LEFT(E8,FIND(" ",E8)-1))*12))
B14: Rendimentos acumulados | E14: =IF(OR(E12="",E13=""),"",E12-E13)
B15: Dividendos mensais | E15: =IF(E12="","",E12*'Premissas da Simulação'!G11)
B16: Meta de renda mensal | E16: ='Objetivo do Investimento'!H10 -> 0
B17: Meta de renda atingida? | E17: =IF(OR(E9="",E9="ESCOLHA"),"",IF(E9="Alcançar um patrimônio específico",IF(E12>=E16,"SIM","NÃO"),IF(E9="Formar patrimônio","NÃO SE APLICA",IF(E15>=E16,"SIM","NÃO"))))

Sheet Resultado
B3: RESULTADO DA SUA SIMULAÇÃO | L3: Voltar para o inicio
D5: ='Premissas da Simulação'!B2
B6: Veja o potencial do seu investimento ao longo do período escolhido. | L6: Voltar para página anterior
B9: Patrimônio acumulado ao final do período | E9: =Simulação!E12 | L9: Imprimir
B10: Total investido | E10: =Simulação!E13
B11: Rendimentos acumulados | E11: =Simulação!E14
B12: Dividendos mensais | E12: =Simulação!E15
B13: Meta de renda mensal | E13: =Simulação!E16 -> 0
B14: Meta de renda atingida? | E14: =Simulação!E17

Sheet Imprimir
B2: RELATÓRIO DA SIMULAÇÃO DE INVESTIMENTO
K3: Voltar para Resultado
B5: Resumo da simulação
B7: Perfil do investidor | C7: ='Perfil do Investidor'!I5 | K7: 🖨️ IMPRIMIR / GERAR PDF
B8: Objetivo | C8: ='Objetivo do Investimento'!G8 -> ESCOLHA
B10: PREMISSAS DA SIMULAÇÃO | I10: “Para gerar o PDF: Ctrl + P → Microsoft Print to PDF → Imprimir.”
B12: Investimento inicial | C12: =Simulação!E6 -> 0
B13: Aporte mensal | C13: =Simulação!E7 -> 0
B14: Prazo | C14: =Simulação!E8 -> ESCOLHA
B15: Rentabilidade mensal estimada | C15: ='Premissas da Simulação'!G8 -> 0
B16: DY mensal estimado | C16: ='Premissas da Simulação'!G11 -> 0
B20: PAPEL | C20: ='Carteira sugerida'!D6 -> 0
B21: TIJOLO | C21: ='Carteira sugerida'!D7 -> 0
B22: HÍBRIDOS | C22: ='Carteira sugerida'!D8 -> 0
B23: FOFs | C23: ='Carteira sugerida'!D9 -> 0
B24: DESENVOLVIMENTO | C24: ='Carteira sugerida'!D10 -> 0
B25: HOTELARIA | C25: ='Carteira sugerida'!D11 -> 0
B26: TOTAL | C26: ='Carteira sugerida'!D12 -> 0
B30: Patrimônio projetado | C30: =Simulação!E12
B31: Total investido | C31: =Simulação!E13
B32: Rendimentos acumulados | C32: =Simulação!E14
B33: Dividendos mensais | C33: =Simulação!E15
B34: Meta de renda mensal | C34: =Simulação!E16 -> 0
B35: Meta de renda atingida? | C35: =Simulação!E17
B37: CONCLUSÃO DA SIMULAÇÃO
B39: =IF(C35="","",IF(C35="SIM","Com base nas premissas utilizadas, a meta financeira informada foi atingida na simulação.","Com base nas premissas utilizadas, a meta financeira informada não foi atingida na simulação."))
B41: Observação: Esta simulação tem caráter exclusivamente educacional. Os resultados são projeções baseadas nas premissas utilizadas e não representam garantia de rentabilidade futura.

Sheet Variáveis
A1: Tipo de FII | B1: Conservador | C1: Moderado | D1: Agressivo
A2: Papel | B2: 0.4 | C2: 0.3 | D2: 0.2
A3: Tijolo | B3: 0.4 | C3: 0.35 | D3: 0.3
A4: Híbridos | B4: 0.1 | C4: 0.1 | D4: 0.1
A5: FOFs | B5: 0.1 | C5: 0.1 | D5: 0.1
A6: Desenvolvimento | B6: 0 | C6: 0.1 | D6: 0.2
A7: Hotelaria | B7: 0 | C7: 0.05 | D7: 0.1
A8: TOTAL | B8: 1 | C8: 1 | D8: 1
